Workbook

Sheet IE
A1: P.T./O.T. EVALUATION
A3: AGENCY NAME: | E3: 111 | O3: BP: | P3: 333 | T3: HR: | U3: 444 | X3: MR: | Y3: 555
A4: PATIENT NAME: | E4: 222 | O4: DIAGNOSIS: | R4: 777
A6: PROBLEMS IDENTIFIED: | P6: SHORT TERM GOAL (4-8 WEEKS):
A7: 888 | P7: 8
A14: LEGEND: Indep - Partially Dep - Supervised - CareGiver Assist - MIN assist - MOD assist - MAX assist - UnAble - Not Tested
A15: BED MOBILITY: | E15: 999 | H15: roll/scoot | K15: =E15 -> 999 | N15: supine to sit | R15: =E15 -> 999 | U15: sit to supine
A16: ADL FUNCTION: | E16: =E15 -> 999 | H16: dressing | K16: =E15 -> 999 | N16: personal hygiene | R16: =E15 -> 999 | U16: bathing | W16: 10 | Z16: FEEDING
E17: =E15 -> 999 | H17: meal prep | K17: =E15 -> 999 | N17: home making
A18: TRANSFERS: | E18: =E15 -> 999 | H18: bed | K18: =E15 -> 999 | N18: wheelchair | R18: =E15 -> 999 | U18: toilet / commode
E19: =E15 -> 999 | H19: shower | K19: =E15 -> 999 | N19: car | R19: =E15 -> 999 | U19: car | W19: =E15 -> 999 | Z19: FLOOR
A20: GAIT DESCRIPTION: | Q20: FUNCTIONAL LIMITATIONS:
A21: ANALYSIS/DEVIATION | G21: 11 | Q21: 17 | R21: amputation | W21: 24 | X21: bowel / bladder
A22: ASSISTIVE DEVICE | G22: 12 | Q22: 18 | R22: DOE/SOB/wheezing | W22: 25 | X22: speech
A23: LEVEL SURFACES | G23: 13 | Q23: 19 | R23: contractures | W23: 26 | X23: hearing
A24: UNEVEN SURFACES | G24: 14 | Q24: 20 | R24: paralysis | W24: 27 | X24: vision
A25: STAIRS / STEP / CURB | G25: 15 | Q25: 21 | R25: weakness | W25: 28 | X25: ambulation
A26: MINUTES/DISTANCE | G26: =G23 -> 13 | Q26: 22 | R26: endurance | W26: 29
A27: WEIGHT BEARING | G27: 16 | Q27: 23 | R27: fracture / surgery | W27: 30
A28: HOMEBOUND REASONS: | N28: COGNITION:
A29: 31 | B29: bed ridden/bed bound | N29: 44 | O29: alert | R29: 47 | S29: oriented | V29: 49 | W29: lethargic | Z29: 51 | AA29: ST memory
A30: 32 | B30: cannot ambulate> | F30: =G23 -> 13 | J30: feet / mins | N30: 45 | O30: confused | R30: 48 | S30: comatose | V30: 50 | W30: agitated | Z30: 52 | AA30: LT memory
A31: 33 | B31: confusion / unable to go out alone | N31: 46
A32: 34 | B32: dependent upon assistive device | N32: BALANCE / TOLERANCE:
A33: 35 | B33: pain limits mobility | T33: STATIC | AA33: DYNAMIC
A34: 36 | B34: needs assistance on all activities | N34: SITTING | Q34: 53 | X34: =Q34 -> 53
A35: 37 | B35: paralysis / weakness / hemiparesis | N35: STANDING | Q35: 54 | X35: =Q35 -> 54
A36: 38 | B36: poor & limited endurance | N36: LIVING SITUATION: | S36: 55
A37: 39 | B37: (+)assist to ambulate / holds onto walls/furniture | N37: PRECAUTIONS: | S37: 56
A38: 40 | B38: severe SOB / SOB on exertion / wheezing | N38: REHAB POTENTIAL: | S38: 57 | T38: poor | V38: 58 | W38: fair | X38: 59 | Y38: good | AA38: 60 | AB38: excellent
A39: 41 | B39: unable to safely leave home unassisted | N39: ROM: all joints are WFL / WNL except for:
A40: 42 | B40: unsteady gait / high risk for falls | N40: 61
A41: 43 | B41: w/c bound w/ no access to stairs, cannot propel | N41: MMT: all paraspinal & both UE/LE are WFL except for:
N42: 62
A43: ACTIVITIES PERMITTED:
A44: 63 | B44: complete bedrest | F44: 65 | G44: bedrest w/ BRP | K44: 67 | L44: transfer bed/chair | Q44: 69 | R44: exercise prescribed | W44: 71 | X44: ambulation w/ assist
A45: 64 | B45: wheelchair | F45: 66 | G45: PWB | K45: 68 | L45: ambulation w/ O2 | Q45: 70 | R45: cane/fww/quad cane/crutches/rollator
A46: WHEELCHAIR SKILLS: | P46: PRIOR LEVEL OF FUNCTION: | W46: PATIENT IS INDEPENDENT IN ALL ASPECTS OF ADL AND SELF-CARE. PATIENT FUNCTIONS WITH MINIMUM TO NO DIFFICULTY
A47: 72
A48: PALPATION: | P48: PAIN (LOCATION / INTENSITY):
...

Sheet DAILY VISIT NOTE
A1: P.T. / O.T. VISIT NOTE
A3: PATIENT NAME: | E3: =IE!E4 -> 222 | P3: AGENCY NAME: | T3: =IE!E3 -> 111
A5: HOMEBOUND REASONS:
A6: =IE!A29 -> 31 | B6: bed ridden/bed bound | R6: =IE!A36 -> 38 | S6: poor & limited endurance
A7: =IE!A30 -> 32 | B7: cannot ambulate> | F7: =IE!F30 -> 13 | L7: feet / mins | R7: =IE!A37 -> 39 | S7: (+)assist to ambulate / holds onto walls/furniture
A8: =IE!A31 -> 33 | B8: confusion / unable to go out alone | R8: =IE!A38 -> 40 | S8: severe SOB / SOB on exertion / wheezing
A9: =IE!A32 -> 34 | B9: dependent upon assistive device | R9: =IE!A39 -> 41 | S9: unable to safely leave home unassisted
A10: =IE!A33 -> 35 | B10: pain limits mobility | R10: =IE!A40 -> 42 | S10: unsteady gait / high risk for falls
A11: =IE!A34 -> 36 | B11: needs assistance on all activities | R11: =IE!A41 -> 43 | S11: w/c bound w/ no access to stairs, cannot propel
A12: =IE!A35 -> 37 | B12: paralysis / weakness / hemiparesis | R12: =IE!A42 | S12: =IE!B42
A14: SERVICES PROVIDED:
A15: X | B15: INITIAL EVALUATION | Q15: ULTRASOUND
B16: DISCHARGE EVALUATION | Q16: IONTOPHORESIS
B17: THERAPEUTIC EXERCISES (STRETCH / STRENGTH) | Q17: UVR / IRR
B18: THERAPEUTIC ACTIVITIES (FUNCTIONAL) | Q18: ELECTROTHERAPY
B19: GAIT TRAINING (W/ & W/O ASSITIVE DEVICE) | Q19: TENS
B20: MANUAL THERAPY (STM / MFR / JOINT MOB / PNF) | Q20: CPM
B21: NEUROMUSCULAR REEDUCATION | P21: X | Q21: TEACH BED MOBILITY SKILLS
B22: BALANCE TRAINING (SITTING / STANDING) | P22: X | Q22: TEACH HIP SAFETY PRECAUTIONS
B23: PROSTHETIC TRAINING | P23: X | Q23: TEACH USE OF ASSISTIVE DEVICE
A24: X | B24: ADL AND SELF CARE TRAINING | P24: X | Q24: TEACH HOME EXERCISE PROGRAM (HEP)
B25: OTHERS: | P25: X | Q25: TEACH PATIENT FALL PRECAUTION
Q26: TEACH WHEELCHAIR SKILLS
A28: OBSERVATIONS & INSTRUCTIONS DURING THIS VISIT (SPECIFIC TREATMENTS GIVEN, PATIENT'S REACTION AND COMMENTS AS WELL SPECIFIC IMPROVEMENTS AND ACHIEVEMENTS FOR THIS VISIT. OTHER PERTINENT FINDINGS AND INFORMATION:
A31: =IE!A7 -> 888
A40: PROGRESS TOWARDS GOAL: | I40: =IE!P7 -> 8
A42: PLAN FOR NEXT VISIT: | I42: =IE!E53 -> 79
A44: DISCHARGE INSTRUCTION: | I44: =IE!R52 -> 78
A45: (ON LAST VISIT)
A46: PAIN (LOCATION / INTENSITY): | I46: =IE!P49 -> 74
A51: =IE!A58 -> Brian Masayon, RPT, CCI | K51: DATE: | M51: =IE!L58 -> 29 | S51: TIME IN: | V51: =IE!M56 -> 27 | Y51: TIME OUT: | AB51: =IE!M57 -> 28
A52: =IE!A59 -> Physical Therapist
A53: =IE!A60 -> Certified Clinical Instructor
A55: ==================================================================================================
A56: PT-RN CARE, INC. | AD56: PT - OT SERVICES
A57: 1663 BEVERLY BLVD SUITE 202 LOS ANGELES CA 90026 | AD57: EMAIL: PTRNCAREINC@SBCGLOBAL.NET
A58: Ph: 213.250.0078 Fax: 213.250.5578 | AD58: WEBSITE: WWW.PTRNCAREINC.COM

Sheet P.O.
A1: P.T. / O.T. TREATMENT ORDER
A3: AGENCY NAME: | E3: =IE!E3 -> 111 | W3: MR: | Y3: =IE!Y3 -> 555
A4: PATIENT NAME: | E4: =IE!E4 -> 222 | W4: DATE:
A6: X | B6: NEW ORDER | Q6: ADDITIONAL ORDER
A8: PROBLEM/S:
A9: =IE!A7 -> 888
A15: SHORT TERM (4-8WEEKS) GOAL/S FOR THIS CERTIFICATION PERIOD:
A16: =IE!P7 -> 8
A22: PLAN OF CARE:
A23: =IE!E53 -> 79
A29: DME/S NEEDED:
A30: =IE!A51 -> 75
A36: COMMENTS:
A37: =IE!P51 -> 76
A41: PT FREQUENCY: | G41: =IE!F52 -> 77
A43: PHYSICIAN NAME:
A44: PHYSICIAN SIGNATURE: | H44: _____________________________________________ | W44: DATE:
A47: =IE!A58 -> Brian Masayon, RPT, CCI
A48: =IE!A59 -> Physical Therapist | L48: =IE!L58 -> 29
A49: =IE!A60 -> Certified Clinical Instructor | J49: Dated:
A51: =================================================================================================
A52: PT-RN CARE, INC. | AD52: PT - OT SERVICES
A53: 1663 BEVERLY BLVD SUITE 202 LOS ANGELES CA 90026 | AD53: EMAIL: PTRNCAREINC@SBCGLOBAL.NET
A54: Ph: 213.250.0078 Fax: 213.250.5578 | AD54: WEBSITE: WWW.PTRNCAREINC.COM

Sheet CN TO PTA
A1: PT-RN CARE, INC.
A2: PHYSICAL THERAPY SERVICES
A3: 1663 BEVERLY BLVD, SUITE 202, LOS ANGELES, CA, 90026
A4: PHONE NO.: (213) 250-00PT (0078); (213) 250-99PT (9978)
A5: Email address: ptrncareinc@sbcglobal.net
A7: COMMUNICATION NOTE – PTA INSTRUCTIONS
A9: DATE: | B9: =IE!L58 -> 29
A11: TO: | B11: =IE!E67 -> 80 | D11: , PTA | I11: MR#: | J11: =IE!Y3 -> 555
A12: AGENCY NAME | B12: =IE!E3 -> 111
A13: PATIENT NAME: | B13: =IE!E4 -> 222
A14: ADDRESS: | B14: =IE!E68 -> 81 | H14: TEL#: | I14: =IE!E69 -> 82
A17: =IE!A7 -> 888
A19: PLEASE SEE PX STARTING | C19: =IE!E70 -> 83 | D19: WEEK. | E19: FREQ. OF | F19: =IE!E71 -> 84 | G19: I WILL SEE PX FOR DC THE AFTER YOUR VISITS.
A20: TOTAL OF | B20: add all pink | C20: VISITS FOR YOU
A22: =IE!A73 -> 85 | F22: =IE!F73 -> 90 | H22: FOLLOW UP VISIT/S
A23: =IE!A74 -> 86 | F23: =IE!F74 -> 91 | H23: FOLLOW UP VISIT/S
A24: =IE!A75 -> 87 | F24: =IE!F75 -> 92 | H24: FOLLOW UP VISIT/S
A25: =IE!A76 -> 88 | F25: =IE!F76 -> 93 | H25: FOLLOW UP VISIT/S
A26: =IE!A77 -> 89 | F26: =IE!F77 -> 94 | H26: FOLLOW UP VISIT/S
A27: =IE!A78 | F27: =IE!F78 | H27: FOLLOW UP VISIT/S
A28: PLAN OF CARE:
A29: ENERGY CONSERVATION TECHNIQUE
A30: STATIONARY BIKE AS TOLERATED ONLY
A31: HOME EXERCISE PROGRAM, SITTING TOLERANCE EXERCISES, BED EXERCISES, STANDING TOLERANCE
A32: CONDITIONING EXERCISE USING BOTH UPPER EXTREMITIES AND LOWER EXTREMITIES
A33: STANDING BALANCE EXERCISES OF BOTH LOWER EXTREMITIES AP
A34: STANDING TOLERANCE TRAINING
A35: GAIT TRAINING AND STEP TRAINING
A36: CORE STRENGTHENING PROGRAM
A37: TRANSFER TRAINING, BED MOBILITY EXERCISES-KEGEL’S EXERCISES
A38: STEP AND STAIR TRAINING
A41: PRECAUTION: | C41: =IE!S37 -> 56
A43: GOALS OF PX:
A44: INCREASE TRANSFER CAPABILTIES AS TO SIT TO STAND/CHAIR
A45: INCREASE MMT BOTH UPPER EXTREMITIES/LOWER EXTREMITIES
A46: INDEPENDENT IN HOME EXERCISES
A47: INDEPENDENT ON GAIT WITHOUT DIFFICULTY
A48: INCREASE BALANCE TO GOOD
A49: RETURN TO PRIOR LEVEL OF FUNCTION WITHOUT DIFFICULTY AND PAIN AND TO BECOME INDEPENDENT ON GAIT AND TRANSFERS, ADL AND SELF-CARE MANAGEMENT
A52: CALL OR TEXT ME IF YOU ARE ON YOUR LAST VISIT WITH THE PATIENT SO THAT I CAN DISCHARGE HIM/HER AFTER YOU SEE HIM/HER. I WILL FAX THIS NOTE ALONG WITH PATIENT'S INFORMATION. I LEFT THE FORMS YOU WILL BE USING ON THE LEFT SIDE POCKET OF THE PATIENT'S FOLDER OF HHA.
...

Sheet TEAM CONFERENCE
A1: TEAM CONFERENCE | W1: Initial Evaluation
A2: AGENCY NAME | F2: =IE!E3 -> 111 | R2: MR# | T2: =IE!Y3 -> 555
A3: PATIENT NAME | F3: =IE!E4 -> 222 | R3: DATE: | T3: =IE!L58 -> 29
A4: SERVICE/S: | E4: SN | G4: X | H4: PT | K4: OT | N4: RT | Q4: MSW | T4: DIETICIAN
A6: SKILLED NURSING | M6: PHYSICAL THERAPY / RESPIRATORY THERAPY
B7: significant changes in general condition | M7: X | N7: difficulty in transfer
B8: questionable medication effectiveness | M8: X | N8: decreased upright tolerance / endurance
B9: impaired wound healing process | N9: change in mental status
B10: symptoms of infection | M10: X | N10: poor safety / balance
B11: nutrition / PO intake | M11: X | N11: decreased ROM / strength
B12: unreliable with MEDS / needs instruction | M12: X | N12: pain
B13: slow to to comprehend medical tx instructions | N13: equipment / prosthesis
B14: poor bowel/bladder management | M14: X | N14: modalities required
B15: complicated medical treatment | N15: difficulty w/ patient / family / follow through
B16: no complications identified | N16: Other/s:
B17: Other/s:
M18: OCCUPATIONAL / RESPIRATORY THERAPY
A19: SOCIAL SERVICES | N19: difficulty with ADLs
B20: living arrangements unsafe or inadequate for level of care | N20: decreased ROM / strength
B21: family unable to cope with situation | N21: decreased upright tolerance / endurance
B22: suspect physical / emotional abuse or neglect | N22: decreased fine / gross motor coordination
B23: patient having difficulty with med tx | N23: problems w/ energy conservation / self pacing
B24: patient is socially isolated | N24: pain
B25: patient needs financial assistamce / placement | N25: difficulty w/ cognitive perception
B26: patient needs community resource help with: | N26: difficulty with patient family follow through
C27: food | F27: longterm care/placement | N27: Other/s:
C28: transportation | G28: financial assitance
B29: Other/s:
A31: COMMENTS / PROGRESS:
A32: =IE!A7 -> 888
A40: RECOMMENDATIONS:
B41: SPEECH THERAPIST | N41: CHHA
B42: RESPIRATORY THERAPIST | N42: DIETICIAN
A44: NAME OF NURSING SUPERVISOR: | K44: RN SIGNATURE:
K46: LVN SIGNATURE:
B48: TELECONFERENCE
B49: ACTUAL MEETING | K49: DISCIPLINE COMPLETING THIS FORM:
K50: X | L50: PT | N50: OT | P50: RT | R50: ST
A51: THERAPIST NAME: | K51: THERAPIST SIGNATURE:
A52: =IE!A58 -> Brian Masayon, RPT, CCI
